Workbook

Sheet Summary
A1: ASG Stress Report Generation - Project Summary
B3: As-of date | C3: 46308 | D3: <- input (blue); drives Overdue / Due-in-7-days flags
B5: By Workstream
B6: Workstream | C6: Total | D6: Complete | E6: In Progress | F6: Not Started | G6: Blocked | H6: Overdue | I6: Avg % Complete
B7: UI | C7: =COUNTIF('Master Plan'!$B$5:$B$73,B7) -> 5 | D7: =COUNTIFS('Master Plan'!$B$5:$B$73,$B7,'Master Plan'!$K$5:$K$73,"Complete") -> 1 | E7: =COUNTIFS('Master Plan'!$B$5:$B$73,$B7,'Master Plan'!$K$5:$K$73,"In Progress") -> 2 | F7: =COUNTIFS('Master Plan'!$B$5:$B$73,$B7,'Master Plan'!$K$5:$K$73,"Not Started") -> 2 | G7: =COUNTIFS('Master Plan'!$B$5:$B$73,$B7,'Master Plan'!$K$5:$K$73,"Blocked") -> 0 | H7: =COUNTIFS('Master Plan'!$B$5:$B$73,$B7,'Master Plan'!$L$5:$L$73,"OVERDUE") -> 1 | I7: =IFERROR(AVERAGEIFS('Master Plan'!$I$5:$I$73,'Master Plan'!$B$5:$B$73,$B7),0) -> 0.26
B8: Backend | C8: =COUNTIF('Master Plan'!$B$5:$B$73,B8) -> 38 | D8: =COUNTIFS('Master Plan'!$B$5:$B$73,$B8,'Master Plan'!$K$5:$K$73,"Complete") -> 4 | E8: =COUNTIFS('Master Plan'!$B$5:$B$73,$B8,'Master Plan'!$K$5:$K$73,"In Progress") -> 2 | F8: =COUNTIFS('Master Plan'!$B$5:$B$73,$B8,'Master Plan'!$K$5:$K$73,"Not Started") -> 8 | G8: =COUNTIFS('Master Plan'!$B$5:$B$73,$B8,'Master Plan'!$K$5:$K$73,"Blocked") -> 24 | H8: =COUNTIFS('Master Plan'!$B$5:$B$73,$B8,'Master Plan'!$L$5:$L$73,"OVERDUE") -> 1 | I8: =IFERROR(AVERAGEIFS('Master Plan'!$I$5:$I$73,'Master Plan'!$B$5:$B$73,$B8),0) -> 0.13421053
B9: API | C9: =COUNTIF('Master Plan'!$B$5:$B$73,B9) -> 7 | D9: =COUNTIFS('Master Plan'!$B$5:$B$73,$B9,'Master Plan'!$K$5:$K$73,"Complete") -> 1 | E9: =COUNTIFS('Master Plan'!$B$5:$B$73,$B9,'Master Plan'!$K$5:$K$73,"In Progress") -> 4 | F9: =COUNTIFS('Master Plan'!$B$5:$B$73,$B9,'Master Plan'!$K$5:$K$73,"Not Started") -> 2 | G9: =COUNTIFS('Master Plan'!$B$5:$B$73,$B9,'Master Plan'!$K$5:$K$73,"Blocked") -> 0 | H9: =COUNTIFS('Master Plan'!$B$5:$B$73,$B9,'Master Plan'!$L$5:$L$73,"OVERDUE") -> 2 | I9: =IFERROR(AVERAGEIFS('Master Plan'!$I$5:$I$73,'Master Plan'!$B$5:$B$73,$B9),0) -> 0.44285714
B10: LLM & RAG | C10: =COUNTIF('Master Plan'!$B$5:$B$73,B10) -> 10 | D10: =COUNTIFS('Master Plan'!$B$5:$B$73,$B10,'Master Plan'!$K$5:$K$73,"Complete") -> 0 | E10: =COUNTIFS('Master Plan'!$B$5:$B$73,$B10,'Master Plan'!$K$5:$K$73,"In Progress") -> 0 | F10: =COUNTIFS('Master Plan'!$B$5:$B$73,$B10,'Master Plan'!$K$5:$K$73,"Not Started") -> 7 | G10: =COUNTIFS('Master Plan'!$B$5:$B$73,$B10,'Master Plan'!$K$5:$K$73,"Blocked") -> 3 | H10: =COUNTIFS('Master Plan'!$B$5:$B$73,$B10,'Master Plan'!$L$5:$L$73,"OVERDUE") -> 0 | I10: =IFERROR(AVERAGEIFS('Master Plan'!$I$5:$I$73,'Master Plan'!$B$5:$B$73,$B10),0) -> 0
B11: Testing & Release | C11: =COUNTIF('Master Plan'!$B$5:$B$73,B11) -> 9 | D11: =COUNTIFS('Master Plan'!$B$5:$B$73,$B11,'Master Plan'!$K$5:$K$73,"Complete") -> 0 | E11: =COUNTIFS('Master Plan'!$B$5:$B$73,$B11,'Master Plan'!$K$5:$K$73,"In Progress") -> 0 | F11: =COUNTIFS('Master Plan'!$B$5:$B$73,$B11,'Master Plan'!$K$5:$K$73,"Not Started") -> 9 | G11: =COUNTIFS('Master Plan'!$B$5:$B$73,$B11,'Master Plan'!$K$5:$K$73,"Blocked") -> 0 | H11: =COUNTIFS('Master Plan'!$B$5:$B$73,$B11,'Master Plan'!$L$5:$L$73,"OVERDUE") -> 0 | I11: =IFERROR(AVERAGEIFS('Master Plan'!$I$5:$I$73,'Master Plan'!$B$5:$B$73,$B11),0) -> 0
B12: Total | C12: =SUM(C7:C11) -> 69 | D12: =SUM(D7:D11) -> 6 | E12: =SUM(E7:E11) -> 8 | F12: =SUM(F7:F11) -> 28 | G12: =SUM(G7:G11) -> 27 | H12: =SUM(H7:H11) -> 4 | I12: =IFERROR(AVERAGE('Master Plan'!$I$5:$I$73),0) -> 0.13768116
B14: By Owner
B15: Owner | C15: Total | D15: Complete | E15: In Progress | F15: Not Started | G15: Blocked | H15: Overdue
B16: Abhik | C16: =COUNTIF('Master Plan'!$E$5:$E$73,B16) -> 12 | D16: =COUNTIFS('Master Plan'!$E$5:$E$73,$B16,'Master Plan'!$K$5:$K$73,"Complete") -> 2 | E16: =COUNTIFS('Master Plan'!$E$5:$E$73,$B16,'Master Plan'!$K$5:$K$73,"In Progress") -> 8 | F16: =COUNTIFS('Master Plan'!$E$5:$E$73,$B16,'Master Plan'!$K$5:$K$73,"Not Started") -> 2 | G16: =COUNTIFS('Master Plan'!$E$5:$E$73,$B16,'Master Plan'!$K$5:$K$73,"Blocked") -> 0 | H16: =COUNTIFS('Master Plan'!$E$5:$E$73,$B16,'Master Plan'!$L$5:$L$73,"OVERDUE") -> 4
B17: Srujan | C17: =COUNTIF('Master Plan'!$E$5:$E$73,B17) -> 5 | D17: =COUNTIFS('Master Plan'!$E$5:$E$73,$B17,'Master Plan'!$K$5:$K$73,"Complete") -> 3 | E17: =COUNTIFS('Master Plan'!$E$5:$E$73,$B17,'Master Plan'!$K$5:$K$73,"In Progress") -> 0 | F17: =COUNTIFS('Master Plan'!$E$5:$E$73,$B17,'Master Plan'!$K$5:$K$73,"Not Started") -> 2 | G17: =COUNTIFS('Master Plan'!$E$5:$E$73,$B17,'Master Plan'!$K$5:$K$73,"Blocked") -> 0 | H17: =COUNTIFS('Master Plan'!$E$5:$E$73,$B17,'Master Plan'!$L$5:$L$73,"OVERDUE") -> 0
B18: Rajesh | C18: =COUNTIF('Master Plan'!$E$5:$E$73,B18) -> 1 | D18: =COUNTIFS('Master Plan'!$E$5:$E$73,$B18,'Master Plan'!$K$5:$K$73,"Complete") -> 0 | E18: =COUNTIFS('Master Plan'!$E$5:$E$73,$B18,'Master Plan'!$K$5:$K$73,"In Progress") -> 0 | F18: =COUNTIFS('Master Plan'!$E$5:$E$73,$B18,'Master Plan'!$K$5:$K$73,"Not Started") -> 1 | G18: =COUNTIFS('Master Plan'!$E$5:$E$73,$B18,'Master Plan'!$K$5:$K$73,"Blocked") -> 0 | H18: =COUNTIFS('Master Plan'!$E$5:$E$73,$B18,'Master Plan'!$L$5:$L$73,"OVERDUE") -> 0
B19: Srujan, Rajesh, Abhik | C19: =COUNTIF('Master Plan'!$E$5:$E$73,B19) -> 10 | D19: =COUNTIFS('Master Plan'!$E$5:$E$73,$B19,'Master Plan'!$K$5:$K$73,"Complete") -> 1 | E19: =COUNTIFS('Master Plan'!$E$5:$E$73,$B19,'Master Plan'!$K$5:$K$73,"In Progress") -> 0 | F19: =COUNTIFS('Master Plan'!$E$5:$E$73,$B19,'Master Plan'!$K$5:$K$73,"Not Started") -> 9 | G19: =COUNTIFS('Master Plan'!$E$5:$E$73,$B19,'Master Plan'!$K$5:$K$73,"Blocked") -> 0 | H19: =COUNTIFS('Master Plan'!$E$5:$E$73,$B19,'Master Plan'!$L$5:$L$73,"OVERDUE") -> 0
B20: Unassigned | C20: =COUNTIF('Master Plan'!$E$5:$E$73,B20) -> 41 | D20: =COUNTIFS('Master Plan'!$E$5:$E$73,$B20,'Master Plan'!$K$5:$K$73,"Complete") -> 0 | E20: =COUNTIFS('Master Plan'!$E$5:$E$73,$B20,'Master Plan'!$K$5:$K$73,"In Progress") -> 0 | F20: =COUNTIFS('Master Plan'!$E$5:$E$73,$B20,'Master Plan'!$K$5:$K$73,"Not Started") -> 14 | G20: =COUNTIFS('Master Plan'!$E$5:$E$73,$B20,'Master Plan'!$K$5:$K$73,"Blocked") -> 27 | H20: =COUNTIFS('Master Plan'!$E$5:$E$73,$B20,'Master Plan'!$L$5:$L$73,"OVERDUE") -> 0
B21: Total | C21: =SUM(C16:C20) -> 69 | D21: =SUM(D16:D20) -> 6 | E21: =SUM(E16:E20) -> 8 | F21: =SUM(F16:F20) -> 28 | G21: =SUM(G16:G20) -> 27 | H21: =SUM(H16:H20) -> 4
B23: Check: owner total = workstream total | C23: =IF(C21=C12,"OK","MISMATCH") -> OK
B25: Legend: blue = input/editable, green = linked from another sheet, black = formula. Colours in Status / Schedule Flag are conditional.
B26: Task Origin & Section Coverage
B27: Item | C27: Count
B28: Tasks from Project Plan | C28: =COUNTIF('Master Plan'!$P$5:$P$73,"Project Plan") -> 54
B29: Tasks proposed from SRG Sections | C29: =COUNTIF('Master Plan'!$P$5:$P$73,"Proposed") -> 15
B30: AR sections (SRG Sections) | C30: =COUNTA('Sections Register'!B8:B21) -> 14
B31: Sections where ASG and ART are NOT aligned | C31: =COUNTIF('Sections Register'!G8:G21,"No") -> 5
B32: Sections covered only by proposed tasks | C32: =COUNTIF('Sections Register'!M8:M21,"Proposed only") -> 3
B33: Sections with no tasks / missing LLM task | C33: =COUNTIF('Sections Register'!M8:M21,"NO TASKS")+COUNTIF('Sections Register'!M8:M21,"LLM task missing") -> 0

Sheet Master Plan
A1: ASG Stress Report Generation - Master Project Plan
A2: Single source of truth (Project Plan tasks + tasks proposed from SRG Sections - see Origin column). Edit blue cells (Owner, Start, Finish, % Complete, Blocked?, Dependency, Notes). Status, Duration, Schedule Flag, workstream tabs and Summary update automatically. As-of date is set on Summary!C3.
A4: ID | B4: Workstream | C4: Feature / Report Section | D4: Task | E4: Owner | F4: Start | G4: Finish | H4: Duration (days) | I4: % Complete | J4: Blocked? | K4: Status | L4: Schedule Flag | M4: Dependency / Blocker | N4: Source Row | O4: Notes | P4: Origin
A5: T-001 | B5: UI | C5: Project Setup | D5: UI folder setup and Login | E5: Abhik | F5: 46286 | G5: 46304 | H5: =IF(OR(F5="",G5=""),"",G5-F5) -> 18 | I5: 1 | J5: No | K5: =IF(J5="Yes","Blocked",IF(I5>=1,"Complete",IF(I5>0,"In Progress","Not Started"))) -> Complete | L5: =IF(K5="Complete","Done",IF(K5="Blocked","Blocked",IF(OR(F5="",G5=""),"No dates",IF(G5<Summary!$C$3,"OVERDUE",IF(G5-Summary!$C$3<=7,"Due in 7 days","On track"))))) -> Done | N5: 2 | P5: Project Plan
A6: T-002 | B6: UI | C6: Header Section | D6: UI design for collecting Header fields info (Engineer name, Date, Model, Report, Revision version) | E6: Abhik | F6: 46293 | G6: 46318 | H6: =IF(OR(F6="",G6=""),"",G6-F6) -> 25 | I6: 0.1 | J6: No | K6: =IF(J6="Yes","Blocked",IF(I6>=1,"Complete",IF(I6>0,"In Progress","Not Started"))) -> In Progress | L6: =IF(K6="Complete","Done",IF(K6="Blocked","Blocked",IF(OR(F6="",G6=""),"No dates",IF(G6<Summary!$C$3,"OVERDUE",IF(G6-Summary!$C$3<=7,"Due in 7 days","On track"))))) -> On track | N6: 6 | O6: Date field added per SRG Sections (ART suggestion 8/10/26) | P6: Project Plan
A7: T-003 | B7: UI | C7: Revision Record Table | D7: UI to collect Revision changes (Revision, Date, Change Description, Approvals) | E7: Abhik | F7: 46304 | G7: 46318 | H7: =IF(OR(F7="",G7=""),"",G7-F7) -> 14 | I7: 0.2 | J7: No | K7: =IF(J7="Yes","Blocked",IF(I7>=1,"Complete",IF(I7>0,"In Progress","Not Started"))) -> In Progress | L7: =IF(K7="Complete","Done",IF(K7="Blocked","Blocked",IF(OR(F7="",G7=""),"No dates",IF(G7<Summary!$C$3,"OVERDUE",IF(G7-Summary!$C$3<=7,"Due in 7 days","On track"))))) -> On track | N7: 10 | O7: Finish date read as 23/16/2026 in source; assumed 23/10/2026. Fields per SRG Sections (first row auto-filled; rest from UI) | P7: Project Plan
A8: T-004 | B8: UI | C8: Component Description | D8: UI to capture Program, Component, Loads | E8: Abhik | F8: 46286 | G8: 46304 | H8: =IF(OR(F8="",G8=""),"",G8-F8) -> 18 | I8: 0 | J8: No | K8: =IF(J8="Yes","Blocked",IF(I8>=1,"Complete",IF(I8>0,"In Progress","Not Started"))) -> Not Started | L8: =IF(K8="Complete","Done",IF(K8="Blocked","Blocked",IF(OR(F8="",G8=""),"No dates",IF(G8<Summary!$C$3,"OVERDUE",IF(G8-Summary!$C$3<=7,"Due in 7 days","On track"))))) -> OVERDUE | N8: 39 | P8: Project Plan
A9: T-005 | B9: UI | C9: FEM Description | D9: UI for uploading BDF and DAT input files | E9: Unassigned | H9: =IF(OR(F9="",G9=""),"",G9-F9) | I9: 0 | J9: No | K9: =IF(J9="Yes","Blocked",IF(I9>=1,"Complete",IF(I9>0,"In Progress","Not Started"))) -> Not Started | L9: =IF(K9="Complete","Done",IF(K9="Blocked","Blocked",IF(OR(F9="",G9=""),"No dates",IF(G9<Summary!$C$3,"OVERDUE",IF(G9-Summary!$C$3<=7,"Due in 7 days","On track"))))) -> No dates | N9: SRG-19 | O9: Proposed: input channel for BDF/DAT not specified in source - confirm | P9: Proposed
A10: T-006 | B10: Backend | C10: Project Setup | D10: Postgres database setup and data model to store login info (local env) | E10: Abhik | F10: 46286 | G10: 46304 | H10: =IF(OR(F10="",G10=""),"",G10-F10) -> 18 | I10: 0.9 | J10: No | K10: =IF(J10="Yes","Blocked",IF(I10>=1,"Complete",IF(I10>0,"In Progress","Not Started"))) -> In Progress | L10: =IF(K10="Complete","Done",IF(K10="Blocked","Blocked",IF(OR(F10="",G10=""),"No dates",IF(G10<Summary!$C$3,"OVERDUE",IF(G10-Summary!$C$3<=7,"Due in 7 days","On track"))))) -> OVERDUE | N10: 3 | P10: Project Plan
A11: T-007 | B11: Backend | C11: Header Section | D11: YAML to add Header section in AR | E11: Srujan | F11: 46293 | G11: 46311 | H11: =IF(OR(F11="",G11=""),"",G11-F11) -> 18 | I11: 1 | J11: No | K11: =IF(J11="Yes","Blocked",IF(I11>=1,"Complete",IF(I11>0,"In Progress","Not Started"))) -> Complete | L11: =IF(K11="Complete","Done",IF(K11="Blocked","Blocked",IF(OR(F11="",G11=""),"No dates",IF(G11<Summary!$C$3,"OVERDUE",IF(G11-Summary!$C$3<=7,"Due in 7 days","On track"))))) -> Done | N11: 8 | P11: Project Plan
A12: T-008 | B12: Backend | C12: Table of Contents | D12: YAML to add TOC section in AR | E12: Srujan | F12: 46293 | G12: 46296 | H12: =IF(OR(F12="",G12=""),"",G12-F12) -> 3 | I12: 1 | J12: No | K12: =IF(J12="Yes","Blocked",IF(I12>=1,"Complete",IF(I12>0,"In Progress","Not Started"))) -> Complete | L12: =IF(K12="Complete","Done",IF(K12="Blocked","Blocked",IF(OR(F12="",G12=""),"No dates",IF(G12<Summary!$C$3,"OVERDUE",IF(G12-Summary!$C$3<=7,"Due in 7 days","On track"))))) -> Done | N12: 9 | P12: Project Plan
A13: T-009 | B13: Backend | C13: Revision Record Table | D13: Data model for saving Revision history (only first revision auto-filled; later revisions manual entry) | E13: Abhik | F13: 46304 | G13: 46318 | H13: =IF(OR(F13="",G13=""),"",G13-F13) -> 14 | I13: 0.2 | J13: No | K13: =IF(J13="Yes","Blocked",IF(I13>=1,"Complete",IF(I13>0,"In Progress","Not Started"))) -> In Progress | L13: =IF(K13="Complete","Done",IF(K13="Blocked","Blocked",IF(OR(F13="",G13=""),"No dates",IF(G13<Summary!$C$3,"OVERDUE",IF(G13-Summary!$C$3<=7,"Due in 7 days","On track"))))) -> On track | N13: 12 | O13: Finish date read as 23/16/2026 in source; assumed 23/10/2026 | P13: Project Plan
A14: T-010 | B14: Backend | C14: Revision Record Table | D14: YAML to add Revision table to AR | E14: Srujan | F14: 46293 | G14: 46311 | H14: =IF(OR(F14="",G14=""),"",G14-F14) -> 18 | I14: 1 | J14: No | K14: =IF(J14="Yes","Blocked",IF(I14>=1,"Complete",IF(I14>0,"In Progress","Not Started"))) -> Complete | L14: =IF(K14="Complete","Done",IF(K14="Blocked","Blocked",IF(OR(F14="",G14=""),"No dates",IF(G14<Summary!$C$3,"OVERDUE",IF(G14-Summary!$C$3<=7,"Due in 7 days","On track"))))) -> Done | N14: 13 | P14: Project Plan
A15: T-011 | B15: Backend | C15: List of Parts | D15: Automation to extract List of Parts from BOMSTR | E15: Unassigned | H15: =IF(OR(F15="",G15=""),"",G15-F15) | I15: 0 | J15: Yes | K15: =IF(J15="Yes","Blocked",IF(I15>=1,"Complete",IF(I15>0,"In Progress","Not Started"))) -> Blocked | L15: =IF(K15="Complete","Done",IF(K15="Blocked","Blocked",IF(OR(F15="",G15=""),"No dates",IF(G15<Summary!$C$3,"OVERDUE",IF(G15-Summary!$C$3<=7,"Due in 7 days","On track"))))) -> Blocked | M15: ASG Team to confirm if BOMSTR or Drawing PDF? | N15: 31 | P15: Project Plan
A16: T-012 | B16: Backend | C16: List of Parts | D16: Automation/OCR to extract List of Parts from Drawing documents | E16: Unassigned | H16: =IF(OR(F16="",G16=""),"",G16-F16) | I16: 0 | J16: Yes | K16: =IF(J16="Yes","Blocked",IF(I16>=1,"Complete",IF(I16>0,"In Progress","Not Started"))) -> Blocked | L16: =IF(K16="Complete","Done",IF(K16="Blocked","Blocked",IF(OR(F16="",G16=""),"No dates",IF(G16<Summary!$C$3,"OVERDUE",IF(G16-Summary!$C$3<=7,"Due in 7 days","On track"))))) -> Blocked | M16: ASG Team to confirm if BOMSTR or Drawing PDF? | N16: 32 | O16: ART recommends BOMSTR instead: drawings only have high-level part numbers (no sub-parts) and OCR needs extra processing (8/10/26) | P16: Project Plan
A17: T-013 | B17: Backend | C17: List of Parts | D17: Automation to download PDF from Teamcenter | E17: Unassigned | H17: =IF(OR(F17="",G17=""),"",G17-F17) | I17: 0 | J17: Yes | K17: =IF(J17="Yes","Blocked",IF(I17>=1,"Complete",IF(I17>0,"In Progress","Not Started"))) -> Blocked | L17: =IF(K17="Complete","Done",IF(K17="Blocked","Blocked",IF(OR(F17="",G17=""),"No dates",IF(G17<Summary!$C$3,"OVERDUE",IF(G17-Summary!$C$3<=7,"Due in 7 days","On track"))))) -> Blocked | M17: ASG Team to provide API access to Teamcenter | N17: 33 | O17: Long-term per ART; Teamcenter API access currently unavailable (8/10/26) | P17: Project Plan
A18: T-014 | B18: Backend | C18: List of Parts | D18: YAML to add List of Parts section in AR | E18: Unassigned | H18: =IF(OR(F18="",G18=""),"",G18-F18) | I18: 0 | J18: Yes | K18: =IF(J18="Yes","Blocked",IF(I18>=1,"Complete",IF(I18>0,"In Progress","Not Started"))) -> Blocked | L18: =IF(K18="Complete","Done",IF(K18="Blocked","Blocked",IF(OR(F18="",G18=""),"No dates",IF(G18<Summary!$C$3,"OVERDUE",IF(G18-Summary!$C$3<=7,"Due in 7 days","On track"))))) -> Blocked | M18: ASG Team to confirm if BOMSTR or Drawing PDF? | N18: 34 | P18: Project Plan
A19: T-015 | B19: Backend | C19: Margin of Safety (MS) Summary | D19: Automation to extract Location ID | E19: Unassigned | H19: =IF(OR(F19="",G19=""),"",G19-F19) | I19: 0 | J19: Yes | K19: =IF(J19="Yes","Blocked",IF(I19>=1,"Complete",IF(I19>0,"In Progress","Not Started"))) -> Blocked | L19: =IF(K19="Complete","Done",IF(K19="Blocked","Blocked",IF(OR(F19="",G19=""),"No dates",IF(G19<Summary!$C$3,"OVERDUE",IF(G19-Summary!$C$3<=7,"Due in 7 days","On track"))))) -> Blocked | M19: ASG Team to provide Location ID for analysis (not feasible to extract from CATIA images) | N19: 35 | O19: Feature grouping inferred. CONFLICT: plan says not feasible from CATIA images; SRG Sections (8/10/26) says Location ID will come from CATIA image - confirm with ASG | P19: Project Plan
A20: T-016 | B20: Backend | C20: Margin of Safety (MS) Summary | D20: Automation to extract Part Number, Material, Temp, Applied Condition/Load ID, Applied Load/Stress, Allowable Load/Stress, Failure Mode, MS | E20: Unassigned | H20: =IF(OR(F20="",G20=""),"",G20-F20) | I20: 0 | J20: Yes | K20: =IF(J20="Yes","Blocked",IF(I20>=1,"Complete",IF(I20>0,"In Progress","Not Started"))) -> Blocked | L20: =IF(K20="Complete","Done",IF(K20="Blocked","Blocked",IF(OR(F20="",G20=""),"No dates",IF(G20<Summary!$C$3,"OVERDUE",IF(G20-Summary!$C$3<=7,"Due in 7 days","On track"))))) -> Blocked | M20: ASG Team to output Part Number, Material, Temp, Load ID, Applied/Allowable Load-Stress, Failure Mode, MS in Excel (confirmed in 5/10/26 meeting) | N20: 36 | O20: MS comes from one-stop stress tool Excel output | P20: Project Plan
A21: T-017 | B21: Backend | C21: Margin of Safety (MS) Summary | D21: Automation to create MOS summary table | E21: Unassigned | H21: =IF(OR(F21="",G21=""),"",G21-F21) | I21: 0 | J21: Yes | K21: =IF(J21="Yes","Blocked",IF(I21>=1,"Complete",IF(I21>0,"In Progress","Not Started"))) -> Blocked | L21: =IF(K21="Complete","Done",IF(K21="Blocked","Blocked",IF(OR(F21="",G21=""),"No dates",IF(G21<Summary!$C$3,"OVERDUE",IF(G21-Summary!$C$3<=7,"Due in 7 days","On track"))))) -> Blocked | M21: ASG Team to output Part Number, Material, Temp, Load ID, Applied/Allowable Load-Stress, Failure Mode, MS in Excel (confirmed in 5/10/26 meeting) | N21: 37 | P21: Project Plan
A22: T-018 | B22: Backend | C22: Margin of Safety (MS) Summary | D22: YAML to add MOS Summary section in AR | E22: Unassigned | H22: =IF(OR(F22="",G22=""),"",G22-F22) | I22: 0 | J22: Yes | K22: =IF(J22="Yes","Blocked",IF(I22>=1,"Complete",IF(I22>0,"In Progress","Not Started"))) -> Blocked | L22: =IF(K22="Complete","Done",IF(K22="Blocked","Blocked",IF(OR(F22="",G22=""),"No dates",IF(G22<Summary!$C$3,"OVERDUE",IF(G22-Summary!$C$3<=7,"Due in 7 days","On track"))))) -> Blocked | M22: ASG Team to output Part Number, Material, Temp, Load ID, Applied/Allowable Load-Stress, Failure Mode, MS in Excel (confirmed in 5/10/26 meeting) | N22: 38 | P22: Project Plan
A23: T-019 | B23: Backend | C23: Component Description | D23: Automation to merge UI and RAG data | E23: Abhik | F23: 46304 | G23: 46318 | H23: =IF(OR(F23="",G23=""),"",G23-F23) -> 14 | I23: 0 | J23: No | K23: =IF(J23="Yes","Blocked",IF(I23>=1,"Complete",IF(I23>0,"In Progress","Not Started"))) -> Not Started | L23: =IF(K23="Complete","Done",IF(K23="Blocked","Blocked",IF(OR(F23="",G23=""),"No dates",IF(G23<Summary!$C$3,"OVERDUE",IF(G23-Summary!$C$3<=7,"Due in 7 days","On track"))))) -> On track | N23: 41 | P23: Project Plan
A24: T-020 | B24: Backend | C24: Component Description | D24: Add images to Component Description | E24: Unassigned | H24: =IF(OR(F24="",G24=""),"",G24-F24) | I24: 0 | J24: Yes | K24: =IF(J24="Yes","Blocked",IF(I24>=1,"Complete",IF(I24>0,"In Progress","Not Started"))) -> Blocked | L24: =IF(K24="Complete","Done",IF(K24="Blocked","Blocked",IF(OR(F24="",G24=""),"No dates",IF(G24<Summary!$C$3,"OVERDUE",IF(G24-Summary!$C$3<=7,"Due in 7 days","On track"))))) -> Blocked | M24: ASG Team to provide Images | N24: 42 | P24: Project Plan
A25: T-021 | B25: Backend | C25: Component Description | D25: YAML to add Component Description section | E25: Srujan | F25: 46304 | G25: 46318 | H25: =IF(OR(F25="",G25=""),"",G25-F25) -> 14 | I25: 0 | J25: No | K25: =IF(J25="Yes","Blocked",IF(I25>=1,"Complete",IF(I25>0,"In Progress","Not Started"))) -> Not Started | L25: =IF(K25="Complete","Done",IF(K25="Blocked","Blocked",IF(OR(F25="",G25=""),"No dates",IF(G25<Summary!$C$3,"OVERDUE",IF(G25-Summary!$C$3<=7,"Due in 7 days","On track"))))) -> On track | N25: 43 | P25: Project Plan
A26: T-022 | B26: Backend | C26: Loads Section | D26: Automation to get Loads information from One Stop Stress tool | E26: Unassigned | H26: =IF(OR(F26="",G26=""),"",G26-F26) | I26: 0 | J26: Yes | K26: =IF(J26="Yes","Blocked",IF(I26>=1,"Complete",IF(I26>0,"In Progress","Not Started"))) -> Blocked | L26: =IF(K26="Complete","Done",IF(K26="Blocked","Blocked",IF(OR(F26="",G26=""),"No dates",IF(G26<Summary!$C$3,"OVERDUE",IF(G26-Summary!$C$3<=7,"Due in 7 days","On track"))))) -> Blocked | M26: ASG Team One Stop Stress tool not ready yet for Loads | N26: 45 | O26: Dependency cell showed 'sr' in source; inferred from adjacent rows | P26: Project Plan
A27: T-023 | B27: Backend | C27: Loads Section | D27: YAML to add Loads section in AR | E27: Unassigned | H27: =IF(OR(F27="",G27=""),"",G27-F27) | I27: 0 | J27: Yes | K27: =IF(J27="Yes","Blocked",IF(I27>=1,"Complete",IF(I27>0,"In Progress","Not Started"))) -> Blocked | L27: =IF(K27="Complete","Done",IF(K27="Blocked","Blocked",IF(OR(F27="",G27=""),"No dates",IF(G27<Summary!$C$3,"OVERDUE",IF(G27-Summary!$C$3<=7,"Due in 7 days","On track"))))) -> Blocked | M27: ASG Team One Stop Stress tool not ready yet for Loads | N27: 46 | P27: Project Plan
A28: T-024 | B28: Backend | C28: Loads Section | D28: Add images to Loads section | E28: Unassigned | H28: =IF(OR(F28="",G28=""),"",G28-F28) | I28: 0 | J28: Yes | K28: =IF(J28="Yes","Blocked",IF(I28>=1,"Complete",IF(I28>0,"In Progress","Not Started"))) -> Blocked | L28: =IF(K28="Complete","Done",IF(K28="Blocked","Blocked",IF(OR(F28="",G28=""),"No dates",IF(G28<Summary!$C$3,"OVERDUE",IF(G28-Summary!$C$3<=7,"Due in 7 days","On track"))))) -> Blocked | M28: ASG Team to provide Images | N28: 47 | P28: Project Plan
A29: T-025 | B29: Backend | C29: Static Analysis Section | D29: Automation to get Static Analysis from One Stop Stress tool | E29: Unassigned | H29: =IF(OR(F29="",G29=""),"",G29-F29) | I29: 0 | J29: Yes | K29: =IF(J29="Yes","Blocked",IF(I29>=1,"Complete",IF(I29>0,"In Progress","Not Started"))) -> Blocked | L29: =IF(K29="Complete","Done",IF(K29="Blocked","Blocked",IF(OR(F29="",G29=""),"No dates",IF(G29<Summary!$C$3,"OVERDUE",IF(G29-Summary!$C$3<=7,"Due in 7 days","On track"))))) -> Blocked | M29: ASG Team One Stop Stress tool not ready yet for Static Analysis | N29: 49 | P29: Project Plan
A30: T-026 | B30: Backend | C30: Static Analysis Section | D30: YAML to add Static Analysis section in AR | E30: Unassigned | H30: =IF(OR(F30="",G30=""),"",G30-F30) | I30: 0 | J30: Yes | K30: =IF(J30="Yes","Blocked",IF(I30>=1,"Complete",IF(I30>0,"In Progress","Not Started"))) -> Blocked | L30: =IF(K30="Complete","Done",IF(K30="Blocked","Blocked",IF(OR(F30="",G30=""),"No dates",IF(G30<Summary!$C$3,"OVERDUE",IF(G30-Summary!$C$3<=7,"Due in 7 days","On track"))))) -> Blocked | M30: ASG Team One Stop Stress tool not ready yet for Static Analysis | N30: 50 | P30: Project Plan
A31: T-027 | B31: Backend | C31: Static Analysis Section | D31: Add images to Static Analysis section | E31: Unassigned | H31: =IF(OR(F31="",G31=""),"",G31-F31) | I31: 0 | J31: Yes | K31: =IF(J31="Yes","Blocked",IF(I31>=1,"Complete",IF(I31>0,"In Progress","Not Started"))) -> Blocked | L31: =IF(K31="Complete","Done",IF(K31="Blocked","Blocked",IF(OR(F31="",G31=""),"No dates",IF(G31<Summary!$C$3,"OVERDUE",IF(G31-Summary!$C$3<=7,"Due in 7 days","On track"))))) -> Blocked | M31: ASG Team to provide Images | N31: 51 | P31: Project Plan
A32: T-028 | B32: Backend | C32: Materials (Metallic) Section | D32: Automation to extract List of Parts from BOMSTR | E32: Unassigned | H32: =IF(OR(F32="",G32=""),"",G32-F32) | I32: 0 | J32: Yes | K32: =IF(J32="Yes","Blocked",IF(I32>=1,"Complete",IF(I32>0,"In Progress","Not Started"))) -> Blocked | L32: =IF(K32="Complete","Done",IF(K32="Blocked","Blocked",IF(OR(F32="",G32=""),"No dates",IF(G32<Summary!$C$3,"OVERDUE",IF(G32-Summary!$C$3<=7,"Due in 7 days","On track"))))) -> Blocked | M32: ASG Team to confirm if BOMSTR or Drawing PDF? | N32: 53 | P32: Project Plan
A33: T-029 | B33: Backend | C33: Materials (Metallic) Section | D33: Automation/OCR to extract List of Parts from Drawing documents | E33: Unassigned | H33: =IF(OR(F33="",G33=""),"",G33-F33) | I33: 0 | J33: Yes | K33: =IF(J33="Yes","Blocked",IF(I33>=1,"Complete",IF(I33>0,"In Progress","Not Started"))) -> Blocked | L33: =IF(K33="Complete","Done",IF(K33="Blocked","Blocked",IF(OR(F33="",G33=""),"No dates",IF(G33<Summary!$C$3,"OVERDUE",IF(G33-Summary!$C$3<=7,"Due in 7 days","On track"))))) -> Blocked | M33: ASG Team to confirm if BOMSTR or Drawing PDF? | N33: 54 | O33: ART recommends BOMSTR instead: drawings only have high-level part numbers (no sub-parts) and OCR needs extra processing (8/10/26) | P33: Project Plan
A34: T-030 | B34: Backend | C34: Materials (Metallic) Section | D34: Automation to download PDF from Teamcenter | E34: Unassigned | H34: =IF(OR(F34="",G34=""),"",G34-F34) | I34: 0 | J34: Yes | K34: =IF(J34="Yes","Blocked",IF(I34>=1,"Complete",IF(I34>0,"In Progress","Not Started"))) -> Blocked | L34: =IF(K34="Complete","Done",IF(K34="Blocked","Blocked",IF(OR(F34="",G34=""),"No dates",IF(G34<Summary!$C$3,"OVERDUE",IF(G34-Summary!$C$3<=7,"Due in 7 days","On track"))))) -> Blocked | M34: ASG Team to provide API access to Teamcenter | N34: 55 | O34: Long-term per ART; Teamcenter API access currently unavailable (8/10/26) | P34: Project Plan
A35: T-031 | B35: Backend | C35: Materials (Metallic) Section | D35: Add images to Materials section | E35: Unassigned | H35: =IF(OR(F35="",G35=""),"",G35-F35) | I35: 0 | J35: Yes | K35: =IF(J35="Yes","Blocked",IF(I35>=1,"Complete",IF(I35>0,"In Progress","Not Started"))) -> Blocked | L35: =IF(K35="Complete","Done",IF(K35="Blocked","Blocked",IF(OR(F35="",G35=""),"No dates",IF(G35<Summary!$C$3,"OVERDUE",IF(G35-Summary!$C$3<=7,"Due in 7 days","On track"))))) -> Blocked | M35: ASG Team to provide Images | N35: 56 | P35: Project Plan
A36: T-032 | B36: Backend | C36: Materials (Metallic) Section | D36: YAML to add Materials section in AR | E36: Unassigned | H36: =IF(OR(F36="",G36=""),"",G36-F36) | I36: 0 | J36: Yes | K36: =IF(J36="Yes","Blocked",IF(I36>=1,"Complete",IF(I36>0,"In Progress","Not Started"))) -> Blocked | L36: =IF(K36="Complete","Done",IF(K36="Blocked","Blocked",IF(OR(F36="",G36=""),"No dates",IF(G36<Summary!$C$3,"OVERDUE",IF(G36-Summary!$C$3<=7,"Due in 7 days","On track"))))) -> Blocked | M36: ASG Team to confirm if BOMSTR or Drawing PDF? | N36: 57 | P36: Project Plan
A37: T-033 | B37: Backend | C37: References Section | D37: Automation for generating Reference section from previous ARs | E37: Unassigned | H37: =IF(OR(F37="",G37=""),"",G37-F37) | I37: 0 | J37: Yes | K37: =IF(J37="Yes","Blocked",IF(I37>=1,"Complete",IF(I37>0,"In Progress","Not Started"))) -> Blocked | L37: =IF(K37="Complete","Done",IF(K37="Blocked","Blocked",IF(OR(F37="",G37=""),"No dates",IF(G37<Summary!$C$3,"OVERDUE",IF(G37-Summary!$C$3<=7,"Due in 7 days","On track"))))) -> Blocked | M37: ASG Team to provide list of ESOMS to component Mapping | N37: 58 | O37: ASG agreed (9/7/26) to provide Excel of ESOMs used in component - not received yet | P37: Project Plan
A38: T-034 | B38: Backend | C38: References Section | D38: YAML to add Reference section in AR | E38: Unassigned | H38: =IF(OR(F38="",G38=""),"",G38-F38) | I38: 0 | J38: Yes | K38: =IF(J38="Yes","Blocked",IF(I38>=1,"Complete",IF(I38>0,"In Progress","Not Started"))) -> Blocked | L38: =IF(K38="Complete","Done",IF(K38="Blocked","Blocked",IF(OR(F38="",G38=""),"No dates",IF(G38<Summary!$C$3,"OVERDUE",IF(G38-Summary!$C$3<=7,"Due in 7 days","On track"))))) -> Blocked | M38: ASG Team to provide list of ESOMS to component Mapping | N38: 59 | P38: Project Plan
A39: T-035 | B39: Backend | C39: Fan Cowl AR - Release & Testing | D39: Generate Report for Fan Cowl AR | E39: Srujan, Rajesh, Abhik | F39: 46304 | G39: 46358 | H39: =IF(OR(F39="",G39=""),"",G39-F39) -> 54 | I39: 1 | J39: No | K39: =IF(J39="Yes","Blocked",IF(I39>=1,"Complete",IF(I39>0,"In Progress","Not Started"))) -> Complete | L39: =IF(K39="Complete","Done",IF(K39="Blocked","Blocked",IF(OR(F39="",G39=""),"No dates",IF(G39<Summary!$C$3,"OVERDUE",IF(G39-Summary!$C$3<=7,"Due in 7 days","On track"))))) -> Done | N39: 60 | O39: Shown as 100% in source although finish date is 2/12/2026 - please verify | P39: Project Plan
A40: T-036 | B40: Backend | C40: Scope Section | D40: YAML to add Scope section in AR | E40: Unassigned | H40: =IF(OR(F40="",G40=""),"",G40-F40) | I40: 0 | J40: No | K40: =IF(J40="Yes","Blocked",IF(I40>=1,"Complete",IF(I40>0,"In Progress","Not Started"))) -> Not Started | L40: =IF(K40="Complete","Done",IF(K40="Blocked","Blocked",IF(OR(F40="",G40=""),"No dates",IF(G40<Summary!$C$3,"OVERDUE",IF(G40-Summary!$C$3<=7,"Due in 7 days","On track"))))) -> No dates | M40: UI to capture Program, Component, Loads | N40: SRG-12 | O40: Proposed from SRG Sections row 12 (Scope not in original plan) | P40: Proposed
A41: T-037 | B41: Backend | C41: Analysis Checklist | D41: Automation to build Analysis Checklist from Failure Mode Matrix Excel | E41: Unassigned | H41: =IF(OR(F41="",G41=""),"",G41-F41) | I41: 0 | J41: No | K41: =IF(J41="Yes","Blocked",IF(I41>=1,"Complete",IF(I41>0,"In Progress","Not Started"))) -> Not Started | L41: =IF(K41="Complete","Done",IF(K41="Blocked","Blocked",IF(OR(F41="",G41=""),"No dates",IF(G41<Summary!$C$3,"OVERDUE",IF(G41-Summary!$C$3<=7,"Due in 7 days","On track"))))) -> No dates | N41: SRG-11 | O41: Proposed. SRG says ART already developed a solution - confirm status / % done | P41: Proposed
...

Sheet UI Tasks
A1: UI Tasks | F1: Tasks | G1: =COUNTIF('Master Plan'!$B$5:$B$73,"UI") -> 5 | H1: Avg % Done | I1: =IFERROR(AVERAGEIFS('Master Plan'!$I$5:$I$73,'Master Plan'!$B$5:$B$73,"UI"),0) -> 0.26
A2: Linked to 'Master Plan' - edit there, this tab updates automatically.
A4: ID | B4: Feature / Report Section | C4: Task | D4: Owner | E4: Start | F4: Finish | G4: % Complete | H4: Status | I4: Schedule Flag | J4: Dependency / Blocker | K4: Origin
A5: =IF('Master Plan'!A5="","",'Master Plan'!A5) -> T-001 | B5: =IF('Master Plan'!C5="","",'Master Plan'!C5) -> Project Setup | C5: =IF('Master Plan'!D5="","",'Master Plan'!D5) -> UI folder setup and Login | D5: =IF('Master Plan'!E5="","",'Master Plan'!E5) -> Abhik | E5: =IF('Master Plan'!F5="","",'Master Plan'!F5) -> 46286 | F5: =IF('Master Plan'!G5="","",'Master Plan'!G5) -> 46304 | G5: =IF('Master Plan'!I5="","",'Master Plan'!I5) -> 1 | H5: =IF('Master Plan'!K5="","",'Master Plan'!K5) -> Complete | I5: =IF('Master Plan'!L5="","",'Master Plan'!L5) -> Done | J5: =IF('Master Plan'!M5="","",'Master Plan'!M5) | K5: =IF('Master Plan'!P5="","",'Master Plan'!P5) -> Project Plan
A6: =IF('Master Plan'!A6="","",'Master Plan'!A6) -> T-002 | B6: =IF('Master Plan'!C6="","",'Master Plan'!C6) -> Header Section | C6: =IF('Master Plan'!D6="","",'Master Plan'!D6) -> UI design for collecting Header fields info (Engineer name, Date, Model, Report, Revision version) | D6: =IF('Master Plan'!E6="","",'Master Plan'!E6) -> Abhik | E6: =IF('Master Plan'!F6="","",'Master Plan'!F6) -> 46293 | F6: =IF('Master Plan'!G6="","",'Master Plan'!G6) -> 46318 | G6: =IF('Master Plan'!I6="","",'Master Plan'!I6) -> 0.1 | H6: =IF('Master Plan'!K6="","",'Master Plan'!K6) -> In Progress | I6: =IF('Master Plan'!L6="","",'Master Plan'!L6) -> On track | J6: =IF('Master Plan'!M6="","",'Master Plan'!M6) | K6: =IF('Master Plan'!P6="","",'Master Plan'!P6) -> Project Plan
A7: =IF('Master Plan'!A7="","",'Master Plan'!A7) -> T-003 | B7: =IF('Master Plan'!C7="","",'Master Plan'!C7) -> Revision Record Table | C7: =IF('Master Plan'!D7="","",'Master Plan'!D7) -> UI to collect Revision changes (Revision, Date, Change Description, Approvals) | D7: =IF('Master Plan'!E7="","",'Master Plan'!E7) -> Abhik | E7: =IF('Master Plan'!F7="","",'Master Plan'!F7) -> 46304 | F7: =IF('Master Plan'!G7="","",'Master Plan'!G7) -> 46318 | G7: =IF('Master Plan'!I7="","",'Master Plan'!I7) -> 0.2 | H7: =IF('Master Plan'!K7="","",'Master Plan'!K7) -> In Progress | I7: =IF('Master Plan'!L7="","",'Master Plan'!L7) -> On track | J7: =IF('Master Plan'!M7="","",'Master Plan'!M7) | K7: =IF('Master Plan'!P7="","",'Master Plan'!P7) -> Project Plan
A8: =IF('Master Plan'!A8="","",'Master Plan'!A8) -> T-004 | B8: =IF('Master Plan'!C8="","",'Master Plan'!C8) -> Component Description | C8: =IF('Master Plan'!D8="","",'Master Plan'!D8) -> UI to capture Program, Component, Loads | D8: =IF('Master Plan'!E8="","",'Master Plan'!E8) -> Abhik | E8: =IF('Master Plan'!F8="","",'Master Plan'!F8) -> 46286 | F8: =IF('Master Plan'!G8="","",'Master Plan'!G8) -> 46304 | G8: =IF('Master Plan'!I8="","",'Master Plan'!I8) -> 0 | H8: =IF('Master Plan'!K8="","",'Master Plan'!K8) -> Not Started | I8: =IF('Master Plan'!L8="","",'Master Plan'!L8) -> OVERDUE | J8: =IF('Master Plan'!M8="","",'Master Plan'!M8) | K8: =IF('Master Plan'!P8="","",'Master Plan'!P8) -> Project Plan
A9: =IF('Master Plan'!A9="","",'Master Plan'!A9) -> T-005 | B9: =IF('Master Plan'!C9="","",'Master Plan'!C9) -> FEM Description | C9: =IF('Master Plan'!D9="","",'Master Plan'!D9) -> UI for uploading BDF and DAT input files | D9: =IF('Master Plan'!E9="","",'Master Plan'!E9) -> Unassigned | E9: =IF('Master Plan'!F9="","",'Master Plan'!F9) | F9: =IF('Master Plan'!G9="","",'Master Plan'!G9) | G9: =IF('Master Plan'!I9="","",'Master Plan'!I9) -> 0 | H9: =IF('Master Plan'!K9="","",'Master Plan'!K9) -> Not Started | I9: =IF('Master Plan'!L9="","",'Master Plan'!L9) -> No dates | J9: =IF('Master Plan'!M9="","",'Master Plan'!M9) | K9: =IF('Master Plan'!P9="","",'Master Plan'!P9) -> Proposed

Sheet Backend Tasks
A1: Backend Tasks | F1: Tasks | G1: =COUNTIF('Master Plan'!$B$5:$B$73,"Backend") -> 38 | H1: Avg % Done | I1: =IFERROR(AVERAGEIFS('Master Plan'!$I$5:$I$73,'Master Plan'!$B$5:$B$73,"Backend"),0) -> 0.13421053
A2: Linked to 'Master Plan' - edit there, this tab updates automatically.
A4: ID | B4: Feature / Report Section | C4: Task | D4: Owner | E4: Start | F4: Finish | G4: % Complete | H4: Status | I4: Schedule Flag | J4: Dependency / Blocker | K4: Origin
A5: =IF('Master Plan'!A10="","",'Master Plan'!A10) -> T-006 | B5: =IF('Master Plan'!C10="","",'Master Plan'!C10) -> Project Setup | C5: =IF('Master Plan'!D10="","",'Master Plan'!D10) -> Postgres database setup and data model to store login info (local env) | D5: =IF('Master Plan'!E10="","",'Master Plan'!E10) -> Abhik | E5: =IF('Master Plan'!F10="","",'Master Plan'!F10) -> 46286 | F5: =IF('Master Plan'!G10="","",'Master Plan'!G10) -> 46304 | G5: =IF('Master Plan'!I10="","",'Master Plan'!I10) -> 0.9 | H5: =IF('Master Plan'!K10="","",'Master Plan'!K10) -> In Progress | I5: =IF('Master Plan'!L10="","",'Master Plan'!L10) -> OVERDUE | J5: =IF('Master Plan'!M10="","",'Master Plan'!M10) | K5: =IF('Master Plan'!P10="","",'Master Plan'!P10) -> Project Plan
A6: =IF('Master Plan'!A11="","",'Master Plan'!A11) -> T-007 | B6: =IF('Master Plan'!C11="","",'Master Plan'!C11) -> Header Section | C6: =IF('Master Plan'!D11="","",'Master Plan'!D11) -> YAML to add Header section in AR | D6: =IF('Master Plan'!E11="","",'Master Plan'!E11) -> Srujan | E6: =IF('Master Plan'!F11="","",'Master Plan'!F11) -> 46293 | F6: =IF('Master Plan'!G11="","",'Master Plan'!G11) -> 46311 | G6: =IF('Master Plan'!I11="","",'Master Plan'!I11) -> 1 | H6: =IF('Master Plan'!K11="","",'Master Plan'!K11) -> Complete | I6: =IF('Master Plan'!L11="","",'Master Plan'!L11) -> Done | J6: =IF('Master Plan'!M11="","",'Master Plan'!M11) | K6: =IF('Master Plan'!P11="","",'Master Plan'!P11) -> Project Plan
A7: =IF('Master Plan'!A12="","",'Master Plan'!A12) -> T-008 | B7: =IF('Master Plan'!C12="","",'Master Plan'!C12) -> Table of Contents | C7: =IF('Master Plan'!D12="","",'Master Plan'!D12) -> YAML to add TOC section in AR | D7: =IF('Master Plan'!E12="","",'Master Plan'!E12) -> Srujan | E7: =IF('Master Plan'!F12="","",'Master Plan'!F12) -> 46293 | F7: =IF('Master Plan'!G12="","",'Master Plan'!G12) -> 46296 | G7: =IF('Master Plan'!I12="","",'Master Plan'!I12) -> 1 | H7: =IF('Master Plan'!K12="","",'Master Plan'!K12) -> Complete | I7: =IF('Master Plan'!L12="","",'Master Plan'!L12) -> Done | J7: =IF('Master Plan'!M12="","",'Master Plan'!M12) | K7: =IF('Master Plan'!P12="","",'Master Plan'!P12) -> Project Plan
A8: =IF('Master Plan'!A13="","",'Master Plan'!A13) -> T-009 | B8: =IF('Master Plan'!C13="","",'Master Plan'!C13) -> Revision Record Table | C8: =IF('Master Plan'!D13="","",'Master Plan'!D13) -> Data model for saving Revision history (only first revision auto-filled; later revisions manual entry) | D8: =IF('Master Plan'!E13="","",'Master Plan'!E13) -> Abhik | E8: =IF('Master Plan'!F13="","",'Master Plan'!F13) -> 46304 | F8: =IF('Master Plan'!G13="","",'Master Plan'!G13) -> 46318 | G8: =IF('Master Plan'!I13="","",'Master Plan'!I13) -> 0.2 | H8: =IF('Master Plan'!K13="","",'Master Plan'!K13) -> In Progress | I8: =IF('Master Plan'!L13="","",'Master Plan'!L13) -> On track | J8: =IF('Master Plan'!M13="","",'Master Plan'!M13) | K8: =IF('Master Plan'!P13="","",'Master Plan'!P13) -> Project Plan
A9: =IF('Master Plan'!A14="","",'Master Plan'!A14) -> T-010 | B9: =IF('Master Plan'!C14="","",'Master Plan'!C14) -> Revision Record Table | C9: =IF('Master Plan'!D14="","",'Master Plan'!D14) -> YAML to add Revision table to AR | D9: =IF('Master Plan'!E14="","",'Master Plan'!E14) -> Srujan | E9: =IF('Master Plan'!F14="","",'Master Plan'!F14) -> 46293 | F9: =IF('Master Plan'!G14="","",'Master Plan'!G14) -> 46311 | G9: =IF('Master Plan'!I14="","",'Master Plan'!I14) -> 1 | H9: =IF('Master Plan'!K14="","",'Master Plan'!K14) -> Complete | I9: =IF('Master Plan'!L14="","",'Master Plan'!L14) -> Done | J9: =IF('Master Plan'!M14="","",'Master Plan'!M14) | K9: =IF('Master Plan'!P14="","",'Master Plan'!P14) -> Project Plan
A10: =IF('Master Plan'!A15="","",'Master Plan'!A15) -> T-011 | B10: =IF('Master Plan'!C15="","",'Master Plan'!C15) -> List of Parts | C10: =IF('Master Plan'!D15="","",'Master Plan'!D15) -> Automation to extract List of Parts from BOMSTR | D10: =IF('Master Plan'!E15="","",'Master Plan'!E15) -> Unassigned | E10: =IF('Master Plan'!F15="","",'Master Plan'!F15) | F10: =IF('Master Plan'!G15="","",'Master Plan'!G15) | G10: =IF('Master Plan'!I15="","",'Master Plan'!I15) -> 0 | H10: =IF('Master Plan'!K15="","",'Master Plan'!K15) -> Blocked | I10: =IF('Master Plan'!L15="","",'Master Plan'!L15) -> Blocked | J10: =IF('Master Plan'!M15="","",'Master Plan'!M15) -> ASG Team to confirm if BOMSTR or Drawing PDF? | K10: =IF('Master Plan'!P15="","",'Master Plan'!P15) -> Project Plan
A11: =IF('Master Plan'!A16="","",'Master Plan'!A16) -> T-012 | B11: =IF('Master Plan'!C16="","",'Master Plan'!C16) -> List of Parts | C11: =IF('Master Plan'!D16="","",'Master Plan'!D16) -> Automation/OCR to extract List of Parts from Drawing documents | D11: =IF('Master Plan'!E16="","",'Master Plan'!E16) -> Unassigned | E11: =IF('Master Plan'!F16="","",'Master Plan'!F16) | F11: =IF('Master Plan'!G16="","",'Master Plan'!G16) | G11: =IF('Master Plan'!I16="","",'Master Plan'!I16) -> 0 | H11: =IF('Master Plan'!K16="","",'Master Plan'!K16) -> Blocked | I11: =IF('Master Plan'!L16="","",'Master Plan'!L16) -> Blocked | J11: =IF('Master Plan'!M16="","",'Master Plan'!M16) -> ASG Team to confirm if BOMSTR or Drawing PDF? | K11: =IF('Master Plan'!P16="","",'Master Plan'!P16) -> Project Plan
A12: =IF('Master Plan'!A17="","",'Master Plan'!A17) -> T-013 | B12: =IF('Master Plan'!C17="","",'Master Plan'!C17) -> List of Parts | C12: =IF('Master Plan'!D17="","",'Master Plan'!D17) -> Automation to download PDF from Teamcenter | D12: =IF('Master Plan'!E17="","",'Master Plan'!E17) -> Unassigned | E12: =IF('Master Plan'!F17="","",'Master Plan'!F17) | F12: =IF('Master Plan'!G17="","",'Master Plan'!G17) | G12: =IF('Master Plan'!I17="","",'Master Plan'!I17) -> 0 | H12: =IF('Master Plan'!K17="","",'Master Plan'!K17) -> Blocked | I12: =IF('Master Plan'!L17="","",'Master Plan'!L17) -> Blocked | J12: =IF('Master Plan'!M17="","",'Master Plan'!M17) -> ASG Team to provide API access to Teamcenter | K12: =IF('Master Plan'!P17="","",'Master Plan'!P17) -> Project Plan
A13: =IF('Master Plan'!A18="","",'Master Plan'!A18) -> T-014 | B13: =IF('Master Plan'!C18="","",'Master Plan'!C18) -> List of Parts | C13: =IF('Master Plan'!D18="","",'Master Plan'!D18) -> YAML to add List of Parts section in AR | D13: =IF('Master Plan'!E18="","",'Master Plan'!E18) -> Unassigned | E13: =IF('Master Plan'!F18="","",'Master Plan'!F18) | F13: =IF('Master Plan'!G18="","",'Master Plan'!G18) | G13: =IF('Master Plan'!I18="","",'Master Plan'!I18) -> 0 | H13: =IF('Master Plan'!K18="","",'Master Plan'!K18) -> Blocked | I13: =IF('Master Plan'!L18="","",'Master Plan'!L18) -> Blocked | J13: =IF('Master Plan'!M18="","",'Master Plan'!M18) -> ASG Team to confirm if BOMSTR or Drawing PDF? | K13: =IF('Master Plan'!P18="","",'Master Plan'!P18) -> Project Plan
A14: =IF('Master Plan'!A19="","",'Master Plan'!A19) -> T-015 | B14: =IF('Master Plan'!C19="","",'Master Plan'!C19) -> Margin of Safety (MS) Summary | C14: =IF('Master Plan'!D19="","",'Master Plan'!D19) -> Automation to extract Location ID | D14: =IF('Master Plan'!E19="","",'Master Plan'!E19) -> Unassigned | E14: =IF('Master Plan'!F19="","",'Master Plan'!F19) | F14: =IF('Master Plan'!G19="","",'Master Plan'!G19) | G14: =IF('Master Plan'!I19="","",'Master Plan'!I19) -> 0 | H14: =IF('Master Plan'!K19="","",'Master Plan'!K19) -> Blocked | I14: =IF('Master Plan'!L19="","",'Master Plan'!L19) -> Blocked | J14: =IF('Master Plan'!M19="","",'Master Plan'!M19) -> ASG Team to provide Location ID for analysis (not feasible to extract from CATIA images) | K14: =IF('Master Plan'!P19="","",'Master Plan'!P19) -> Project Plan
A15: =IF('Master Plan'!A20="","",'Master Plan'!A20) -> T-016 | B15: =IF('Master Plan'!C20="","",'Master Plan'!C20) -> Margin of Safety (MS) Summary | C15: =IF('Master Plan'!D20="","",'Master Plan'!D20) -> Automation to extract Part Number, Material, Temp, Applied Condition/Load ID, Applied Load/Stress, Allowable Load/Stress, Failure Mode, MS | D15: =IF('Master Plan'!E20="","",'Master Plan'!E20) -> Unassigned | E15: =IF('Master Plan'!F20="","",'Master Plan'!F20) | F15: =IF('Master Plan'!G20="","",'Master Plan'!G20) | G15: =IF('Master Plan'!I20="","",'Master Plan'!I20) -> 0 | H15: =IF('Master Plan'!K20="","",'Master Plan'!K20) -> Blocked | I15: =IF('Master Plan'!L20="","",'Master Plan'!L20) -> Blocked | J15: =IF('Master Plan'!M20="","",'Master Plan'!M20) -> ASG Team to output Part Number, Material, Temp, Load ID, Applied/Allowable Load-Stress, Failure Mode, MS in Excel (confirmed in 5/10/26 meeting) | K15: =IF('Master Plan'!P20="","",'Master Plan'!P20) -> Project Plan
A16: =IF('Master Plan'!A21="","",'Master Plan'!A21) -> T-017 | B16: =IF('Master Plan'!C21="","",'Master Plan'!C21) -> Margin of Safety (MS) Summary | C16: =IF('Master Plan'!D21="","",'Master Plan'!D21) -> Automation to create MOS summary table | D16: =IF('Master Plan'!E21="","",'Master Plan'!E21) -> Unassigned | E16: =IF('Master Plan'!F21="","",'Master Plan'!F21) | F16: =IF('Master Plan'!G21="","",'Master Plan'!G21) | G16: =IF('Master Plan'!I21="","",'Master Plan'!I21) -> 0 | H16: =IF('Master Plan'!K21="","",'Master Plan'!K21) -> Blocked | I16: =IF('Master Plan'!L21="","",'Master Plan'!L21) -> Blocked | J16: =IF('Master Plan'!M21="","",'Master Plan'!M21) -> ASG Team to output Part Number, Material, Temp, Load ID, Applied/Allowable Load-Stress, Failure Mode, MS in Excel (confirmed in 5/10/26 meeting) | K16: =IF('Master Plan'!P21="","",'Master Plan'!P21) -> Project Plan
... A42: =IF('Master Plan'!A47="","",'Master Plan'!A47) -> T-043 | B42: =IF('Master Plan'!C47="","",'Master Plan'!C47) -> Appendix | C42: =IF('Master Plan'!D47="","",'Master Plan'!D47) -> YAML to add Appendix section in AR | D42: =IF('Master Plan'!E47="","",'Master Plan'!E47) -> Unassigned | E42: =IF('Master Plan'!F47="","",'Master Plan'!F47) | F42: =IF('Master Plan'!G47="","",'Master Plan'!G47) | G42: =IF('Master Plan'!I47="","",'Master Plan'!I47) -> 0 | H42: =IF('Master Plan'!K47="","",'Master Plan'!K47) -> Not Started | I42: =IF('Master Plan'!L47="","",'Master Plan'!L47) -> No dates | J42: =IF('Master Plan'!M47="","",'Master Plan'!M47) | K42: =IF('Master Plan'!P47="","",'Master Plan'!P47) -> Proposed

Sheet API Tasks
A1: API Tasks | F1: Tasks | G1: =COUNTIF('Master Plan'!$B$5:$B$73,"API") -> 7 | H1: Avg % Done | I1: =IFERROR(AVERAGEIFS('Master Plan'!$I$5:$I$73,'Master Plan'!$B$5:$B$73,"API"),0) -> 0.44285714
A2: Linked to 'Master Plan' - edit there, this tab updates automatically.
A4: ID | B4: Feature / Report Section | C4: Task | D4: Owner | E4: Start | F4: Finish | G4: % Complete | H4: Status | I4: Schedule Flag | J4: Dependency / Blocker | K4: Origin
A5: =IF('Master Plan'!A48="","",'Master Plan'!A48) -> T-044 | B5: =IF('Master Plan'!C48="","",'Master Plan'!C48) -> Project Setup | C5: =IF('Master Plan'!D48="","",'Master Plan'!D48) -> API for login page | D5: =IF('Master Plan'!E48="","",'Master Plan'!E48) -> Abhik | E5: =IF('Master Plan'!F48="","",'Master Plan'!F48) -> 46286 | F5: =IF('Master Plan'!G48="","",'Master Plan'!G48) -> 46304 | G5: =IF('Master Plan'!I48="","",'Master Plan'!I48) -> 0.9 | H5: =IF('Master Plan'!K48="","",'Master Plan'!K48) -> In Progress | I5: =IF('Master Plan'!L48="","",'Master Plan'!L48) -> OVERDUE | J5: =IF('Master Plan'!M48="","",'Master Plan'!M48) | K5: =IF('Master Plan'!P48="","",'Master Plan'!P48) -> Project Plan
A6: =IF('Master Plan'!A49="","",'Master Plan'!A49) -> T-045 | B6: =IF('Master Plan'!C49="","",'Master Plan'!C49) -> Project Setup | C6: =IF('Master Plan'!D49="","",'Master Plan'!D49) -> API layer folder setup (local env) | D6: =IF('Master Plan'!E49="","",'Master Plan'!E49) -> Abhik | E6: =IF('Master Plan'!F49="","",'Master Plan'!F49) -> 46286 | F6: =IF('Master Plan'!G49="","",'Master Plan'!G49) -> 46304 | G6: =IF('Master Plan'!I49="","",'Master Plan'!I49) -> 0.9 | H6: =IF('Master Plan'!K49="","",'Master Plan'!K49) -> In Progress | I6: =IF('Master Plan'!L49="","",'Master Plan'!L49) -> OVERDUE | J6: =IF('Master Plan'!M49="","",'Master Plan'!M49) | K6: =IF('Master Plan'!P49="","",'Master Plan'!P49) -> Project Plan
A7: =IF('Master Plan'!A50="","",'Master Plan'!A50) -> T-046 | B7: =IF('Master Plan'!C50="","",'Master Plan'!C50) -> Header Section | C7: =IF('Master Plan'!D50="","",'Master Plan'!D50) -> API design to add Header fields to Word template | D7: =IF('Master Plan'!E50="","",'Master Plan'!E50) -> Abhik | E7: =IF('Master Plan'!F50="","",'Master Plan'!F50) -> 46293 | F7: =IF('Master Plan'!G50="","",'Master Plan'!G50) -> 46318 | G7: =IF('Master Plan'!I50="","",'Master Plan'!I50) -> 0.1 | H7: =IF('Master Plan'!K50="","",'Master Plan'!K50) -> In Progress | I7: =IF('Master Plan'!L50="","",'Master Plan'!L50) -> On track | J7: =IF('Master Plan'!M50="","",'Master Plan'!M50) | K7: =IF('Master Plan'!P50="","",'Master Plan'!P50) -> Project Plan
A8: =IF('Master Plan'!A51="","",'Master Plan'!A51) -> T-047 | B8: =IF('Master Plan'!C51="","",'Master Plan'!C51) -> Revision Record Table | C8: =IF('Master Plan'!D51="","",'Master Plan'!D51) -> API design to add Revision fields to table | D8: =IF('Master Plan'!E51="","",'Master Plan'!E51) -> Abhik | E8: =IF('Master Plan'!F51="","",'Master Plan'!F51) -> 46304 | F8: =IF('Master Plan'!G51="","",'Master Plan'!G51) -> 46318 | G8: =IF('Master Plan'!I51="","",'Master Plan'!I51) -> 0.2 | H8: =IF('Master Plan'!K51="","",'Master Plan'!K51) -> In Progress | I8: =IF('Master Plan'!L51="","",'Master Plan'!L51) -> On track | J8: =IF('Master Plan'!M51="","",'Master Plan'!M51) | K8: =IF('Master Plan'!P51="","",'Master Plan'!P51) -> Project Plan
A9: =IF('Master Plan'!A52="","",'Master Plan'!A52) -> T-048 | B9: =IF('Master Plan'!C52="","",'Master Plan'!C52) -> Analysis Checklist | C9: =IF('Master Plan'!D52="","",'Master Plan'!D52) -> API for reading Failure Mode Matrix spreadsheet | D9: =IF('Master Plan'!E52="","",'Master Plan'!E52) -> Abhik | E9: =IF('Master Plan'!F52="","",'Master Plan'!F52) -> 46286 | F9: =IF('Master Plan'!G52="","",'Master Plan'!G52) -> 46304 | G9: =IF('Master Plan'!I52="","",'Master Plan'!I52) -> 1 | H9: =IF('Master Plan'!K52="","",'Master Plan'!K52) -> Complete | I9: =IF('Master Plan'!L52="","",'Master Plan'!L52) -> Done | J9: =IF('Master Plan'!M52="","",'Master Plan'!M52) -> Not considered - previous ARs will be used | K9: =IF('Master Plan'!P52="","",'Master Plan'!P52) -> Project Plan
A10: =IF('Master Plan'!A53="","",'Master Plan'!A53) -> T-049 | B10: =IF('Master Plan'!C53="","",'Master Plan'!C53) -> Scope Section | C10: =IF('Master Plan'!D53="","",'Master Plan'!D53) -> API to store/serve Program, Component, Loads inputs (shared by Scope and Component Description) | D10: =IF('Master Plan'!E53="","",'Master Plan'!E53) -> Unassigned | E10: =IF('Master Plan'!F53="","",'Master Plan'!F53) | F10: =IF('Master Plan'!G53="","",'Master Plan'!G53) | G10: =IF('Master Plan'!I53="","",'Master Plan'!I53) -> 0 | H10: =IF('Master Plan'!K53="","",'Master Plan'!K53) -> Not Started | I10: =IF('Master Plan'!L53="","",'Master Plan'!L53) -> No dates | J10: =IF('Master Plan'!M53="","",'Master Plan'!M53) | K10: =IF('Master Plan'!P53="","",'Master Plan'!P53) -> Proposed
A11: =IF('Master Plan'!A54="","",'Master Plan'!A54) -> T-050 | B11: =IF('Master Plan'!C54="","",'Master Plan'!C54) -> FEM Description | C11: =IF('Master Plan'!D54="","",'Master Plan'!D54) -> API to receive BDF/DAT files and return extracted FEM attributes | D11: =IF('Master Plan'!E54="","",'Master Plan'!E54) -> Unassigned | E11: =IF('Master Plan'!F54="","",'Master Plan'!F54) | F11: =IF('Master Plan'!G54="","",'Master Plan'!G54) | G11: =IF('Master Plan'!I54="","",'Master Plan'!I54) -> 0 | H11: =IF('Master Plan'!K54="","",'Master Plan'!K54) -> Not Started | I11: =IF('Master Plan'!L54="","",'Master Plan'!L54) -> No dates | J11: =IF('Master Plan'!M54="","",'Master Plan'!M54) | K11: =IF('Master Plan'!P54="","",'Master Plan'!P54) -> Proposed

Sheet LLM & RAG Tasks
A1: LLM & RAG Tasks | F1: Tasks | G1: =COUNTIF('Master Plan'!$B$5:$B$73,"LLM & RAG") -> 10 | H1: Avg % Done | I1: =IFERROR(AVERAGEIFS('Master Plan'!$I$5:$I$73,'Master Plan'!$B$5:$B$73,"LLM & RAG"),0) -> 0
A2: Linked to 'Master Plan' - edit there, this tab updates automatically.
A4: ID | B4: Feature / Report Section | C4: Task | D4: Owner | E4: Start | F4: Finish | G4: % Complete | H4: Status | I4: Schedule Flag | J4: Dependency / Blocker | K4: Origin
A5: =IF('Master Plan'!A55="","",'Master Plan'!A55) -> T-051 | B5: =IF('Master Plan'!C55="","",'Master Plan'!C55) -> Component Description | C5: =IF('Master Plan'!D55="","",'Master Plan'!D55) -> RAG to populate Connection Type, Load Path | D5: =IF('Master Plan'!E55="","",'Master Plan'!E55) -> Rajesh | E5: =IF('Master Plan'!F55="","",'Master Plan'!F55) -> 46304 | F5: =IF('Master Plan'!G55="","",'Master Plan'!G55) -> 46318 | G5: =IF('Master Plan'!I55="","",'Master Plan'!I55) -> 0 | H5: =IF('Master Plan'!K55="","",'Master Plan'!K55) -> Not Started | I5: =IF('Master Plan'!L55="","",'Master Plan'!L55) -> On track | J5: =IF('Master Plan'!M55="","",'Master Plan'!M55) | K5: =IF('Master Plan'!P55="","",'Master Plan'!P55) -> Project Plan
A6: =IF('Master Plan'!A56="","",'Master Plan'!A56) -> T-052 | B6: =IF('Master Plan'!C56="","",'Master Plan'!C56) -> Component Description | C6: =IF('Master Plan'!D56="","",'Master Plan'!D56) -> LLM generation for Component Description | D6: =IF('Master Plan'!E56="","",'Master Plan'!E56) -> Srujan | E6: =IF('Master Plan'!F56="","",'Master Plan'!F56) -> 46304 | F6: =IF('Master Plan'!G56="","",'Master Plan'!G56) -> 46318 | G6: =IF('Master Plan'!I56="","",'Master Plan'!I56) -> 0 | H6: =IF('Master Plan'!K56="","",'Master Plan'!K56) -> Not Started | I6: =IF('Master Plan'!L56="","",'Master Plan'!L56) -> On track | J6: =IF('Master Plan'!M56="","",'Master Plan'!M56) | K6: =IF('Master Plan'!P56="","",'Master Plan'!P56) -> Project Plan
A7: =IF('Master Plan'!A57="","",'Master Plan'!A57) -> T-053 | B7: =IF('Master Plan'!C57="","",'Master Plan'!C57) -> Loads Section | C7: =IF('Master Plan'!D57="","",'Master Plan'!D57) -> LLM generation for Loads section in AR | D7: =IF('Master Plan'!E57="","",'Master Plan'!E57) -> Unassigned | E7: =IF('Master Plan'!F57="","",'Master Plan'!F57) | F7: =IF('Master Plan'!G57="","",'Master Plan'!G57) | G7: =IF('Master Plan'!I57="","",'Master Plan'!I57) -> 0 | H7: =IF('Master Plan'!K57="","",'Master Plan'!K57) -> Blocked | I7: =IF('Master Plan'!L57="","",'Master Plan'!L57) -> Blocked | J7: =IF('Master Plan'!M57="","",'Master Plan'!M57) -> ASG Team One Stop Stress tool not ready yet for Loads | K7: =IF('Master Plan'!P57="","",'Master Plan'!P57) -> Project Plan
A8: =IF('Master Plan'!A58="","",'Master Plan'!A58) -> T-054 | B8: =IF('Master Plan'!C58="","",'Master Plan'!C58) -> Static Analysis Section | C8: =IF('Master Plan'!D58="","",'Master Plan'!D58) -> LLM generation for Static Analysis section in AR (step-by-step calculation paragraphs) | D8: =IF('Master Plan'!E58="","",'Master Plan'!E58) -> Unassigned | E8: =IF('Master Plan'!F58="","",'Master Plan'!F58) | F8: =IF('Master Plan'!G58="","",'Master Plan'!G58) | G8: =IF('Master Plan'!I58="","",'Master Plan'!I58) -> 0 | H8: =IF('Master Plan'!K58="","",'Master Plan'!K58) -> Blocked | I8: =IF('Master Plan'!L58="","",'Master Plan'!L58) -> Blocked | J8: =IF('Master Plan'!M58="","",'Master Plan'!M58) -> ASG Team One Stop Stress tool not ready yet for Static Analysis | K8: =IF('Master Plan'!P58="","",'Master Plan'!P58) -> Project Plan
A9: =IF('Master Plan'!A59="","",'Master Plan'!A59) -> T-055 | B9: =IF('Master Plan'!C59="","",'Master Plan'!C59) -> Fan Cowl AR - Release & Testing | C9: =IF('Master Plan'!D59="","",'Master Plan'!D59) -> RAG pipeline testing | D9: =IF('Master Plan'!E59="","",'Master Plan'!E59) -> Srujan, Rajesh, Abhik | E9: =IF('Master Plan'!F59="","",'Master Plan'!F59) -> 46304 | F9: =IF('Master Plan'!G59="","",'Master Plan'!G59) -> 46358 | G9: =IF('Master Plan'!I59="","",'Master Plan'!I59) -> 0 | H9: =IF('Master Plan'!K59="","",'Master Plan'!K59) -> Not Started | I9: =IF('Master Plan'!L59="","",'Master Plan'!L59) -> On track | J9: =IF('Master Plan'!M59="","",'Master Plan'!M59) | K9: =IF('Master Plan'!P59="","",'Master Plan'!P59) -> Project Plan
A10: =IF('Master Plan'!A60="","",'Master Plan'!A60) -> T-056 | B10: =IF('Master Plan'!C60="","",'Master Plan'!C60) -> Fan Cowl AR - Release & Testing | C10: =IF('Master Plan'!D60="","",'Master Plan'!D60) -> Testing LLM-generated text / RAG pipeline | D10: =IF('Master Plan'!E60="","",'Master Plan'!E60) -> Srujan, Rajesh, Abhik | E10: =IF('Master Plan'!F60="","",'Master Plan'!F60) -> 46304 | F10: =IF('Master Plan'!G60="","",'Master Plan'!G60) -> 46358 | G10: =IF('Master Plan'!I60="","",'Master Plan'!I60) -> 0 | H10: =IF('Master Plan'!K60="","",'Master Plan'!K60) -> Not Started | I10: =IF('Master Plan'!L60="","",'Master Plan'!L60) -> On track | J10: =IF('Master Plan'!M60="","",'Master Plan'!M60) | K10: =IF('Master Plan'!P60="","",'Master Plan'!P60) -> Project Plan
A11: =IF('Master Plan'!A61="","",'Master Plan'!A61) -> T-057 | B11: =IF('Master Plan'!C61="","",'Master Plan'!C61) -> Environment & RAG Setup | C11: =IF('Master Plan'!D61="","",'Master Plan'!D61) -> RAG pipeline setup | D11: =IF('Master Plan'!E61="","",'Master Plan'!E61) -> Unassigned | E11: =IF('Master Plan'!F61="","",'Master Plan'!F61) | F11: =IF('Master Plan'!G61="","",'Master Plan'!G61) | G11: =IF('Master Plan'!I61="","",'Master Plan'!I61) -> 0 | H11: =IF('Master Plan'!K61="","",'Master Plan'!K61) -> Not Started | I11: =IF('Master Plan'!L61="","",'Master Plan'!L61) -> No dates | J11: =IF('Master Plan'!M61="","",'Master Plan'!M61) | K11: =IF('Master Plan'!P61="","",'Master Plan'!P61) -> Project Plan
A12: =IF('Master Plan'!A62="","",'Master Plan'!A62) -> T-058 | B12: =IF('Master Plan'!C62="","",'Master Plan'!C62) -> Scope Section | C12: =IF('Master Plan'!D62="","",'Master Plan'!D62) -> LLM generation for Scope paragraph (from Program, Component, Loads) | D12: =IF('Master Plan'!E62="","",'Master Plan'!E62) -> Unassigned | E12: =IF('Master Plan'!F62="","",'Master Plan'!F62) | F12: =IF('Master Plan'!G62="","",'Master Plan'!G62) | G12: =IF('Master Plan'!I62="","",'Master Plan'!I62) -> 0 | H12: =IF('Master Plan'!K62="","",'Master Plan'!K62) -> Not Started | I12: =IF('Master Plan'!L62="","",'Master Plan'!L62) -> No dates | J12: =IF('Master Plan'!M62="","",'Master Plan'!M62) -> UI to capture Program, Component, Loads | K12: =IF('Master Plan'!P62="","",'Master Plan'!P62) -> Proposed
A13: =IF('Master Plan'!A63="","",'Master Plan'!A63) -> T-059 | B13: =IF('Master Plan'!C63="","",'Master Plan'!C63) -> FEM Description | C13: =IF('Master Plan'!D63="","",'Master Plan'!D63) -> LLM generation for FEM Description (single paragraph from BDF/DAT attributes) | D13: =IF('Master Plan'!E63="","",'Master Plan'!E63) -> Unassigned | E13: =IF('Master Plan'!F63="","",'Master Plan'!F63) | F13: =IF('Master Plan'!G63="","",'Master Plan'!G63) | G13: =IF('Master Plan'!I63="","",'Master Plan'!I63) -> 0 | H13: =IF('Master Plan'!K63="","",'Master Plan'!K63) -> Not Started | I13: =IF('Master Plan'!L63="","",'Master Plan'!L63) -> No dates | J13: =IF('Master Plan'!M63="","",'Master Plan'!M63) -> Automation to parse BDF/DAT | K13: =IF('Master Plan'!P63="","",'Master Plan'!P63) -> Proposed
A14: =IF('Master Plan'!A64="","",'Master Plan'!A64) -> T-060 | B14: =IF('Master Plan'!C64="","",'Master Plan'!C64) -> Materials (Metallic) Section | C14: =IF('Master Plan'!D64="","",'Master Plan'!D64) -> LLM generation for Materials section | D14: =IF('Master Plan'!E64="","",'Master Plan'!E64) -> Unassigned | E14: =IF('Master Plan'!F64="","",'Master Plan'!F64) | F14: =IF('Master Plan'!G64="","",'Master Plan'!G64) | G14: =IF('Master Plan'!I64="","",'Master Plan'!I64) -> 0 | H14: =IF('Master Plan'!K64="","",'Master Plan'!K64) -> Blocked | I14: =IF('Master Plan'!L64="","",'Master Plan'!L64) -> Blocked | J14: =IF('Master Plan'!M64="","",'Master Plan'!M64) -> ASG Team to confirm if BOMSTR or Drawing PDF? | K14: =IF('Master Plan'!P64="","",'Master Plan'!P64) -> Proposed

Sheet Testing & Release
A1: Testing & Release Tasks | F1: Tasks | G1: =COUNTIF('Master Plan'!$B$5:$B$73,"Testing & Release") -> 9 | H1: Avg % Done | I1: =IFERROR(AVERAGEIFS('Master Plan'!$I$5:$I$73,'Master Plan'!$B$5:$B$73,"Testing & Release"),0) -> 0
A2: Linked to 'Master Plan' - edit there, this tab updates automatically.
A4: ID | B4: Feature / Report Section | C4: Task | D4: Owner | E4: Start | F4: Finish | G4: % Complete | H4: Status | I4: Schedule Flag | J4: Dependency / Blocker | K4: Origin
A5: =IF('Master Plan'!A65="","",'Master Plan'!A65) -> T-061 | B5: =IF('Master Plan'!C65="","",'Master Plan'!C65) -> Fan Cowl AR - Release & Testing | C5: =IF('Master Plan'!D65="","",'Master Plan'!D65) -> Deployment of code to pre-prod server | D5: =IF('Master Plan'!E65="","",'Master Plan'!E65) -> Srujan, Rajesh, Abhik | E5: =IF('Master Plan'!F65="","",'Master Plan'!F65) -> 46304 | F5: =IF('Master Plan'!G65="","",'Master Plan'!G65) -> 46358 | G5: =IF('Master Plan'!I65="","",'Master Plan'!I65) -> 0 | H5: =IF('Master Plan'!K65="","",'Master Plan'!K65) -> Not Started | I5: =IF('Master Plan'!L65="","",'Master Plan'!L65) -> On track | J5: =IF('Master Plan'!M65="","",'Master Plan'!M65) | K5: =IF('Master Plan'!P65="","",'Master Plan'!P65) -> Project Plan
